<robot name = "robot">
    <link name="Torso">
        <inertial>
            <origin xyz="0 0 3" rpy="0 0 0"/>
            <mass value="1" />
            <inertia ixx="100" ixy="0" ixz="0" iyy="100" iyz="0" izz="100" />
        </inertial>
        <visual>
            <origin xyz="0 0 3" rpy="0 0 0"/>
            <geometry>
                <box size="2 2 1" />
            </geometry>
            <material name="Cyan">
                <color rgba="0 1 1 1"/>
            </material>
        </visual>
        <collision>
            <origin xyz="0 0 3" rpy="0 0 0"/>
            <geometry>
                <box size="2 2 1" />
            </geometry>
        </collision>
    </link>
    <joint name="Torso_limb0link0" type="revolute">
       <parent link="Torso"/>
       <child  link="limb0link0"/>
       <origin rpy="0 0 0" xyz="1 1 3.0" />
     <axis xyz="1 1 0"/>
       <limit effort="0.0" lower="-3.14159" upper="3.14159" velocity="0.0"/>
    </joint>
    <link name="limb0link0">
        <inertial>
            <origin xyz="0.4359850377479634 0.4359850377479634 0.0" rpy="0 0 0"/>
            <mass value="1" />
            <inertia ixx="100" ixy="0" ixz="0" iyy="100" iyz="0" izz="100" />
        </inertial>
        <visual>
            <origin xyz="0.4359850377479634 0.4359850377479634 0.0" rpy="0 0 0"/>
            <geometry>
                <box size="0.8719700754959268 0.8719700754959268 0.8719700754959268" />
            </geometry>
            <material name="Green">
                <color rgba="0 1 0 1"/>
            </material>
        </visual>
        <collision>
            <origin xyz="0.4359850377479634 0.4359850377479634 0.0" rpy="0 0 0"/>
            <geometry>
                <box size="0.8719700754959268 0.8719700754959268 0.8719700754959268" />
            </geometry>
        </collision>
    </link>
    <joint name="limb0link0_limb0link1" type="revolute">
       <parent link="limb0link0"/>
       <child  link="limb0link1"/>
       <origin rpy="0 0 0" xyz="0.0 0.4359850377479634 -0.4359850377479634" />
     <axis xyz="1 0 1"/>
       <limit effort="0.0" lower="-3.14159" upper="3.14159" velocity="0.0"/>
    </joint>
    <link name="limb0link1">
        <inertial>
            <origin xyz="-0.3352428102266014 0.0 -0.3352428102266014" rpy="0 0 0"/>
            <mass value="1" />
            <inertia ixx="100" ixy="0" ixz="0" iyy="100" iyz="0" izz="100" />
        </inertial>
        <visual>
            <origin xyz="-0.3352428102266014 0.0 -0.3352428102266014" rpy="0 0 0"/>
            <geometry>
                <box size="0.6704856204532028 0.6704856204532028 0.6704856204532028" />
            </geometry>
            <material name="Cyan">
                <color rgba="0 1 1 1"/>
            </material>
        </visual>
        <collision>
            <origin xyz="-0.3352428102266014 0.0 -0.3352428102266014" rpy="0 0 0"/>
            <geometry>
                <box size="0.6704856204532028 0.6704856204532028 0.6704856204532028" />
            </geometry>
        </collision>
    </link>
    <joint name="limb0link1_limb0link2" type="revolute">
       <parent link="limb0link1"/>
       <child  link="limb0link2"/>
       <origin rpy="0 0 0" xyz="-0.3352428102266014 -0.3352428102266014 -0.6704856204532028" />
     <axis xyz="0 1 1"/>
       <limit effort="0.0" lower="-3.14159" upper="3.14159" velocity="0.0"/>
    </joint>
    <link name="limb0link2">
        <inertial>
            <origin xyz="0.0 -0.1538514410794308 -0.1538514410794308" rpy="0 0 0"/>
            <mass value="1" />
            <inertia ixx="100" ixy="0" ixz="0" iyy="100" iyz="0" izz="100" />
        </inertial>
        <visual>
            <origin xyz="0.0 -0.1538514410794308 -0.1538514410794308" rpy="0 0 0"/>
            <geometry>
                <box size="0.3077028821588616 0.3077028821588616 0.3077028821588616" />
            </geometry>
            <material name="Green">
                <color rgba="0 1 0 1"/>
            </material>
        </visual>
        <collision>
            <origin xyz="0.0 -0.1538514410794308 -0.1538514410794308" rpy="0 0 0"/>
            <geometry>
                <box size="0.3077028821588616 0.3077028821588616 0.3077028821588616" />
            </geometry>
        </collision>
    </link>
    <joint name="Torso_limb1link0" type="revolute">
       <parent link="Torso"/>
       <child  link="limb1link0"/>
       <origin rpy="0 0 0" xyz="1 -1 3.0" />
     <axis xyz="1 1 0"/>
       <limit effort="0.0" lower="-3.14159" upper="3.14159" velocity="0.0"/>
    </joint>
    <link name="limb1link0">
        <inertial>
            <origin xyz="0.3802615692707314 -0.3802615692707314 0.0" rpy="0 0 0"/>
            <mass value="1" />
            <inertia ixx="100" ixy="0" ixz="0" iyy="100" iyz="0" izz="100" />
        </inertial>
        <visual>
            <origin xyz="0.3802615692707314 -0.3802615692707314 0.0" rpy="0 0 0"/>
            <geometry>
                <box size="0.7605231385414628 0.7605231385414628 0.7605231385414628" />
            </geometry>
            <material name="Green">
                <color rgba="0 1 0 1"/>
            </material>
        </visual>
        <collision>
            <origin xyz="0.3802615692707314 -0.3802615692707314 0.0" rpy="0 0 0"/>
            <geometry>
                <box size="0.7605231385414628 0.7605231385414628 0.7605231385414628" />
            </geometry>
        </collision>
    </link>
    <joint name="limb1link0_limb1link1" type="revolute">
       <parent link="limb1link0"/>
       <child  link="limb1link1"/>
       <origin rpy="0 0 0" xyz="0.0 -0.7605231385414628 0.0" />
     <axis xyz="1 1 0"/>
       <limit effort="0.0" lower="-3.14159" upper="3.14159" velocity="0.0"/>
    </joint>
    <link name="limb1link1">
        <inertial>
            <origin xyz="-0.2072231571662349 -0.2072231571662349 0.0" rpy="0 0 0"/>
            <mass value="1" />
            <inertia ixx="100" ixy="0" ixz="0" iyy="100" iyz="0" izz="100" />
        </inertial>
        <visual>
            <origin xyz="-0.2072231571662349 -0.2072231571662349 0.0" rpy="0 0 0"/>
            <geometry>
                <box size="0.4144463143324698 0.4144463143324698 0.4144463143324698" />
            </geometry>
            <material name="Green">
                <color rgba="0 1 0 1"/>
            </material>
        </visual>
        <collision>
            <origin xyz="-0.2072231571662349 -0.2072231571662349 0.0" rpy="0 0 0"/>
            <geometry>
                <box size="0.4144463143324698 0.4144463143324698 0.4144463143324698" />
            </geometry>
        </collision>
    </link>
    <joint name="Torso_limb2link0" type="revolute">
       <parent link="Torso"/>
       <child  link="limb2link0"/>
       <origin rpy="0 0 0" xyz="-1 1 3.0" />
     <axis xyz="1 1 0"/>
       <limit effort="0.0" lower="-3.14159" upper="3.14159" velocity="0.0"/>
    </joint>
    <link name="limb2link0">
        <inertial>
            <origin xyz="-0.4359850377479634 0.4359850377479634 0.0" rpy="0 0 0"/>
            <mass value="1" />
            <inertia ixx="100" ixy="0" ixz="0" iyy="100" iyz="0" izz="100" />
        </inertial>
        <visual>
            <origin xyz="-0.4359850377479634 0.4359850377479634 0.0" rpy="0 0 0"/>
            <geometry>
                <box size="0.8719700754959268 0.8719700754959268 0.8719700754959268" />
            </geometry>
            <material name="Green">
                <color rgba="0 1 0 1"/>
            </material>
        </visual>
        <collision>
            <origin xyz="-0.4359850377479634 0.4359850377479634 0.0" rpy="0 0 0"/>
            <geometry>
                <box size="0.8719700754959268 0.8719700754959268 0.8719700754959268" />
            </geometry>
        </collision>
    </link>
    <joint name="limb2link0_limb2link1" type="revolute">
       <parent link="limb2link0"/>
       <child  link="limb2link1"/>
       <origin rpy="0 0 0" xyz="0.0 0.4359850377479634 -0.4359850377479634" />
     <axis xyz="1 0 1"/>
       <limit effort="0.0" lower="-3.14159" upper="3.14159" velocity="0.0"/>
    </joint>
    <link name="limb2link1">
        <inertial>
            <origin xyz="0.3352428102266014 0.0 -0.3352428102266014" rpy="0 0 0"/>
            <mass value="1" />
            <inertia ixx="100" ixy="0" ixz="0" iyy="100" iyz="0" izz="100" />
        </inertial>
        <visual>
            <origin xyz="0.3352428102266014 0.0 -0.3352428102266014" rpy="0 0 0"/>
            <geometry>
                <box size="0.6704856204532028 0.6704856204532028 0.6704856204532028" />
            </geometry>
            <material name="Cyan">
                <color rgba="0 1 1 1"/>
            </material>
        </visual>
        <collision>
            <origin xyz="0.3352428102266014 0.0 -0.3352428102266014" rpy="0 0 0"/>
            <geometry>
                <box size="0.6704856204532028 0.6704856204532028 0.6704856204532028" />
            </geometry>
        </collision>
    </link>
    <joint name="limb2link1_limb2link2" type="revolute">
       <parent link="limb2link1"/>
       <child  link="limb2link2"/>
       <origin rpy="0 0 0" xyz="0.3352428102266014 -0.3352428102266014 -0.6704856204532028" />
     <axis xyz="0 1 1"/>
       <limit effort="0.0" lower="-3.14159" upper="3.14159" velocity="0.0"/>
    </joint>
    <link name="limb2link2">
        <inertial>
            <origin xyz="0.0 -0.1538514410794308 -0.1538514410794308" rpy="0 0 0"/>
            <mass value="1" />
            <inertia ixx="100" ixy="0" ixz="0" iyy="100" iyz="0" izz="100" />
        </inertial>
        <visual>
            <origin xyz="0.0 -0.1538514410794308 -0.1538514410794308" rpy="0 0 0"/>
            <geometry>
                <box size="0.3077028821588616 0.3077028821588616 0.3077028821588616" />
            </geometry>
            <material name="Green">
                <color rgba="0 1 0 1"/>
            </material>
        </visual>
        <collision>
            <origin xyz="0.0 -0.1538514410794308 -0.1538514410794308" rpy="0 0 0"/>
            <geometry>
                <box size="0.3077028821588616 0.3077028821588616 0.3077028821588616" />
            </geometry>
        </collision>
    </link>
    <joint name="Torso_limb3link0" type="revolute">
       <parent link="Torso"/>
       <child  link="limb3link0"/>
       <origin rpy="0 0 0" xyz="-1 -1 3.0" />
     <axis xyz="1 1 0"/>
       <limit effort="0.0" lower="-3.14159" upper="3.14159" velocity="0.0"/>
    </joint>
    <link name="limb3link0">
        <inertial>
            <origin xyz="-0.3802615692707314 -0.3802615692707314 0.0" rpy="0 0 0"/>
            <mass value="1" />
            <inertia ixx="100" ixy="0" ixz="0" iyy="100" iyz="0" izz="100" />
        </inertial>
        <visual>
            <origin xyz="-0.3802615692707314 -0.3802615692707314 0.0" rpy="0 0 0"/>
            <geometry>
                <box size="0.7605231385414628 0.7605231385414628 0.7605231385414628" />
            </geometry>
            <material name="Green">
                <color rgba="0 1 0 1"/>
            </material>
        </visual>
        <collision>
            <origin xyz="-0.3802615692707314 -0.3802615692707314 0.0" rpy="0 0 0"/>
            <geometry>
                <box size="0.7605231385414628 0.7605231385414628 0.7605231385414628" />
            </geometry>
        </collision>
    </link>
    <joint name="limb3link0_limb3link1" type="revolute">
       <parent link="limb3link0"/>
       <child  link="limb3link1"/>
       <origin rpy="0 0 0" xyz="0.0 -0.7605231385414628 0.0" />
     <axis xyz="1 1 0"/>
       <limit effort="0.0" lower="-3.14159" upper="3.14159" velocity="0.0"/>
    </joint>
    <link name="limb3link1">
        <inertial>
            <origin xyz="0.2072231571662349 -0.2072231571662349 0.0" rpy="0 0 0"/>
            <mass value="1" />
            <inertia ixx="100" ixy="0" ixz="0" iyy="100" iyz="0" izz="100" />
        </inertial>
        <visual>
            <origin xyz="0.2072231571662349 -0.2072231571662349 0.0" rpy="0 0 0"/>
            <geometry>
                <box size="0.4144463143324698 0.4144463143324698 0.4144463143324698" />
            </geometry>
            <material name="Green">
                <color rgba="0 1 0 1"/>
            </material>
        </visual>
        <collision>
            <origin xyz="0.2072231571662349 -0.2072231571662349 0.0" rpy="0 0 0"/>
            <geometry>
                <box size="0.4144463143324698 0.4144463143324698 0.4144463143324698" />
            </geometry>
        </collision>
    </link>
</robot>