<robot name = "robot">
    <link name="Torso">
        <inertial>
            <origin xyz="0 0 3" rpy="0 0 0"/>
            <mass value="1" />
            <inertia ixx="100" ixy="0" ixz="0" iyy="100" iyz="0" izz="100" />
        </inertial>
        <visual>
            <origin xyz="0 0 3" rpy="0 0 0"/>
            <geometry>
                <box size="2 2 1" />
            </geometry>
            <material name="Cyan">
                <color rgba="0 1 1 1"/>
            </material>
        </visual>
        <collision>
            <origin xyz="0 0 3" rpy="0 0 0"/>
            <geometry>
                <box size="2 2 1" />
            </geometry>
        </collision>
    </link>
    <joint name="Torso_limb0link0" type="revolute">
       <parent link="Torso"/>
       <child  link="limb0link0"/>
       <origin rpy="0 0 0" xyz="1 1 3.0" />
     <axis xyz="1 1 0"/>
       <limit effort="0.0" lower="-3.14159" upper="3.14159" velocity="0.0"/>
    </joint>
    <link name="limb0link0">
        <inertial>
            <origin xyz="0.24050952237732132 0.24050952237732132 0.0" rpy="0 0 0"/>
            <mass value="1" />
            <inertia ixx="100" ixy="0" ixz="0" iyy="100" iyz="0" izz="100" />
        </inertial>
        <visual>
            <origin xyz="0.24050952237732132 0.24050952237732132 0.0" rpy="0 0 0"/>
            <geometry>
                <box size="0.48101904475464263 0.48101904475464263 0.48101904475464263" />
            </geometry>
            <material name="Cyan">
                <color rgba="0 1 1 1"/>
            </material>
        </visual>
        <collision>
            <origin xyz="0.24050952237732132 0.24050952237732132 0.0" rpy="0 0 0"/>
            <geometry>
                <box size="0.48101904475464263 0.48101904475464263 0.48101904475464263" />
            </geometry>
        </collision>
    </link>
    <joint name="limb0link0_limb0link1" type="revolute">
       <parent link="limb0link0"/>
       <child  link="limb0link1"/>
       <origin rpy="0 0 0" xyz="0.24050952237732132 0.24050952237732132 -0.24050952237732132" />
     <axis xyz="0 0 1"/>
       <limit effort="0.0" lower="-3.14159" upper="3.14159" velocity="0.0"/>
    </joint>
    <link name="limb0link1">
        <inertial>
            <origin xyz="0.0 0.0 -0.38815824279527567" rpy="0 0 0"/>
            <mass value="1" />
            <inertia ixx="100" ixy="0" ixz="0" iyy="100" iyz="0" izz="100" />
        </inertial>
        <visual>
            <origin xyz="0.0 0.0 -0.38815824279527567" rpy="0 0 0"/>
            <geometry>
                <box size="0.7763164855905513 0.7763164855905513 0.7763164855905513" />
            </geometry>
            <material name="Green">
                <color rgba="0 1 0 1"/>
            </material>
        </visual>
        <collision>
            <origin xyz="0.0 0.0 -0.38815824279527567" rpy="0 0 0"/>
            <geometry>
                <box size="0.7763164855905513 0.7763164855905513 0.7763164855905513" />
            </geometry>
        </collision>
    </link>
    <joint name="limb0link1_limb0link2" type="revolute">
       <parent link="limb0link1"/>
       <child  link="limb0link2"/>
       <origin rpy="0 0 0" xyz="0.0 0.0 -0.7763164855905513" />
     <axis xyz="0 0 1"/>
       <limit effort="0.0" lower="-3.14159" upper="3.14159" velocity="0.0"/>
    </joint>
    <link name="limb0link2">
        <inertial>
            <origin xyz="0.0 0.0 -0.167530098172168" rpy="0 0 0"/>
            <mass value="1" />
            <inertia ixx="100" ixy="0" ixz="0" iyy="100" iyz="0" izz="100" />
        </inertial>
        <visual>
            <origin xyz="0.0 0.0 -0.167530098172168" rpy="0 0 0"/>
            <geometry>
                <box size="0.335060196344336 0.335060196344336 0.335060196344336" />
            </geometry>
            <material name="Cyan">
                <color rgba="0 1 1 1"/>
            </material>
        </visual>
        <collision>
            <origin xyz="0.0 0.0 -0.167530098172168" rpy="0 0 0"/>
            <geometry>
                <box size="0.335060196344336 0.335060196344336 0.335060196344336" />
            </geometry>
        </collision>
    </link>
    <joint name="limb0link2_limb0link3" type="revolute">
       <parent link="limb0link2"/>
       <child  link="limb0link3"/>
       <origin rpy="0 0 0" xyz="0.0 -0.167530098172168 -0.167530098172168" />
     <axis xyz="0 1 0"/>
       <limit effort="0.0" lower="-3.14159" upper="3.14159" velocity="0.0"/>
    </joint>
    <link name="limb0link3">
        <inertial>
            <origin xyz="0.0 -0.19688683106596772 0.0" rpy="0 0 0"/>
            <mass value="1" />
            <inertia ixx="100" ixy="0" ixz="0" iyy="100" iyz="0" izz="100" />
        </inertial>
        <visual>
            <origin xyz="0.0 -0.19688683106596772 0.0" rpy="0 0 0"/>
            <geometry>
                <box size="0.39377366213193543 0.39377366213193543 0.39377366213193543" />
            </geometry>
            <material name="Green">
                <color rgba="0 1 0 1"/>
            </material>
        </visual>
        <collision>
            <origin xyz="0.0 -0.19688683106596772 0.0" rpy="0 0 0"/>
            <geometry>
                <box size="0.39377366213193543 0.39377366213193543 0.39377366213193543" />
            </geometry>
        </collision>
    </link>
    <joint name="Torso_limb1link0" type="revolute">
       <parent link="Torso"/>
       <child  link="limb1link0"/>
       <origin rpy="0 0 0" xyz="1 -1 3.0" />
     <axis xyz="1 1 0"/>
       <limit effort="0.0" lower="-3.14159" upper="3.14159" velocity="0.0"/>
    </joint>
    <link name="limb1link0">
        <inertial>
            <origin xyz="0.2736644494311915 -0.2736644494311915 0.0" rpy="0 0 0"/>
            <mass value="1" />
            <inertia ixx="100" ixy="0" ixz="0" iyy="100" iyz="0" izz="100" />
        </inertial>
        <visual>
            <origin xyz="0.2736644494311915 -0.2736644494311915 0.0" rpy="0 0 0"/>
            <geometry>
                <box size="0.547328898862383 0.547328898862383 0.547328898862383" />
            </geometry>
            <material name="Cyan">
                <color rgba="0 1 1 1"/>
            </material>
        </visual>
        <collision>
            <origin xyz="0.2736644494311915 -0.2736644494311915 0.0" rpy="0 0 0"/>
            <geometry>
                <box size="0.547328898862383 0.547328898862383 0.547328898862383" />
            </geometry>
        </collision>
    </link>
    <joint name="limb1link0_limb1link1" type="revolute">
       <parent link="limb1link0"/>
       <child  link="limb1link1"/>
       <origin rpy="0 0 0" xyz="0.0 -0.2736644494311915 0.0" />
     <axis xyz="1 0 0"/>
       <limit effort="0.0" lower="-3.14159" upper="3.14159" velocity="0.0"/>
    </joint>
    <link name="limb1link1">
        <inertial>
            <origin xyz="-0.16810323933524254 0.0 0.0" rpy="0 0 0"/>
            <mass value="1" />
            <inertia ixx="100" ixy="0" ixz="0" iyy="100" iyz="0" izz="100" />
        </inertial>
        <visual>
            <origin xyz="-0.16810323933524254 0.0 0.0" rpy="0 0 0"/>
            <geometry>
                <box size="0.3362064786704851 0.3362064786704851 0.3362064786704851" />
            </geometry>
            <material name="Cyan">
                <color rgba="0 1 1 1"/>
            </material>
        </visual>
        <collision>
            <origin xyz="-0.16810323933524254 0.0 0.0" rpy="0 0 0"/>
            <geometry>
                <box size="0.3362064786704851 0.3362064786704851 0.3362064786704851" />
            </geometry>
        </collision>
    </link>
    <joint name="limb1link1_limb1link2" type="revolute">
       <parent link="limb1link1"/>
       <child  link="limb1link2"/>
       <origin rpy="0 0 0" xyz="-0.16810323933524254 -0.16810323933524254 0.0" />
     <axis xyz="0 1 0"/>
       <limit effort="0.0" lower="-3.14159" upper="3.14159" velocity="0.0"/>
    </joint>
    <link name="limb1link2">
        <inertial>
            <origin xyz="0.0 -0.26786954496454096 0.0" rpy="0 0 0"/>
            <mass value="1" />
            <inertia ixx="100" ixy="0" ixz="0" iyy="100" iyz="0" izz="100" />
        </inertial>
        <visual>
            <origin xyz="0.0 -0.26786954496454096 0.0" rpy="0 0 0"/>
            <geometry>
                <box size="0.1985187761498 0.5357390899290819 0.5262749742979467" />
            </geometry>
            <material name="Green">
                <color rgba="0 1 0 1"/>
            </material>
        </visual>
        <collision>
            <origin xyz="0.0 -0.26786954496454096 0.0" rpy="0 0 0"/>
            <geometry>
                <box size="0.1985187761498 0.5357390899290819 0.5262749742979467" />
            </geometry>
        </collision>
    </link>
    <joint name="limb1link2_limb1link3" type="revolute">
       <parent link="limb1link2"/>
       <child  link="limb1link3"/>
       <origin rpy="0 0 0" xyz="-0.0992593880749 -0.5357390899290819 0.0" />
     <axis xyz="1 1 0"/>
       <limit effort="0.0" lower="-3.14159" upper="3.14159" velocity="0.0"/>
    </joint>
    <link name="limb1link3">
        <inertial>
            <origin xyz="-0.20127494426595943 -0.20127494426595943 0.0" rpy="0 0 0"/>
            <mass value="1" />
            <inertia ixx="100" ixy="0" ixz="0" iyy="100" iyz="0" izz="100" />
        </inertial>
        <visual>
            <origin xyz="-0.20127494426595943 -0.20127494426595943 0.0" rpy="0 0 0"/>
            <geometry>
                <box size="0.40254988853191886 0.40254988853191886 0.40254988853191886" />
            </geometry>
            <material name="Green">
                <color rgba="0 1 0 1"/>
            </material>
        </visual>
        <collision>
            <origin xyz="-0.20127494426595943 -0.20127494426595943 0.0" rpy="0 0 0"/>
            <geometry>
                <box size="0.40254988853191886 0.40254988853191886 0.40254988853191886" />
            </geometry>
        </collision>
    </link>
    <joint name="Torso_limb2link0" type="revolute">
       <parent link="Torso"/>
       <child  link="limb2link0"/>
       <origin rpy="0 0 0" xyz="-1 1 3.0" />
     <axis xyz="1 1 0"/>
       <limit effort="0.0" lower="-3.14159" upper="3.14159" velocity="0.0"/>
    </joint>
    <link name="limb2link0">
        <inertial>
            <origin xyz="-0.24050952237732132 0.24050952237732132 0.0" rpy="0 0 0"/>
            <mass value="1" />
            <inertia ixx="100" ixy="0" ixz="0" iyy="100" iyz="0" izz="100" />
        </inertial>
        <visual>
            <origin xyz="-0.24050952237732132 0.24050952237732132 0.0" rpy="0 0 0"/>
            <geometry>
                <box size="0.48101904475464263 0.48101904475464263 0.48101904475464263" />
            </geometry>
            <material name="Cyan">
                <color rgba="0 1 1 1"/>
            </material>
        </visual>
        <collision>
            <origin xyz="-0.24050952237732132 0.24050952237732132 0.0" rpy="0 0 0"/>
            <geometry>
                <box size="0.48101904475464263 0.48101904475464263 0.48101904475464263" />
            </geometry>
        </collision>
    </link>
    <joint name="limb2link0_limb2link1" type="revolute">
       <parent link="limb2link0"/>
       <child  link="limb2link1"/>
       <origin rpy="0 0 0" xyz="-0.24050952237732132 0.24050952237732132 -0.24050952237732132" />
     <axis xyz="0 0 1"/>
       <limit effort="0.0" lower="-3.14159" upper="3.14159" velocity="0.0"/>
    </joint>
    <link name="limb2link1">
        <inertial>
            <origin xyz="0.0 0.0 -0.38815824279527567" rpy="0 0 0"/>
            <mass value="1" />
            <inertia ixx="100" ixy="0" ixz="0" iyy="100" iyz="0" izz="100" />
        </inertial>
        <visual>
            <origin xyz="0.0 0.0 -0.38815824279527567" rpy="0 0 0"/>
            <geometry>
                <box size="0.7763164855905513 0.7763164855905513 0.7763164855905513" />
            </geometry>
            <material name="Green">
                <color rgba="0 1 0 1"/>
            </material>
        </visual>
        <collision>
            <origin xyz="0.0 0.0 -0.38815824279527567" rpy="0 0 0"/>
            <geometry>
                <box size="0.7763164855905513 0.7763164855905513 0.7763164855905513" />
            </geometry>
        </collision>
    </link>
    <joint name="limb2link1_limb2link2" type="revolute">
       <parent link="limb2link1"/>
       <child  link="limb2link2"/>
       <origin rpy="0 0 0" xyz="0.0 0.0 -0.7763164855905513" />
     <axis xyz="0 0 1"/>
       <limit effort="0.0" lower="-3.14159" upper="3.14159" velocity="0.0"/>
    </joint>
    <link name="limb2link2">
        <inertial>
            <origin xyz="0.0 0.0 -0.167530098172168" rpy="0 0 0"/>
            <mass value="1" />
            <inertia ixx="100" ixy="0" ixz="0" iyy="100" iyz="0" izz="100" />
        </inertial>
        <visual>
            <origin xyz="0.0 0.0 -0.167530098172168" rpy="0 0 0"/>
            <geometry>
                <box size="0.335060196344336 0.335060196344336 0.335060196344336" />
            </geometry>
            <material name="Cyan">
                <color rgba="0 1 1 1"/>
            </material>
        </visual>
        <collision>
            <origin xyz="0.0 0.0 -0.167530098172168" rpy="0 0 0"/>
            <geometry>
                <box size="0.335060196344336 0.335060196344336 0.335060196344336" />
            </geometry>
        </collision>
    </link>
    <joint name="limb2link2_limb2link3" type="revolute">
       <parent link="limb2link2"/>
       <child  link="limb2link3"/>
       <origin rpy="0 0 0" xyz="0.0 -0.167530098172168 -0.167530098172168" />
     <axis xyz="0 1 0"/>
       <limit effort="0.0" lower="-3.14159" upper="3.14159" velocity="0.0"/>
    </joint>
    <link name="limb2link3">
        <inertial>
            <origin xyz="0.0 -0.19688683106596772 0.0" rpy="0 0 0"/>
            <mass value="1" />
            <inertia ixx="100" ixy="0" ixz="0" iyy="100" iyz="0" izz="100" />
        </inertial>
        <visual>
            <origin xyz="0.0 -0.19688683106596772 0.0" rpy="0 0 0"/>
            <geometry>
                <box size="0.39377366213193543 0.39377366213193543 0.39377366213193543" />
            </geometry>
            <material name="Green">
                <color rgba="0 1 0 1"/>
            </material>
        </visual>
        <collision>
            <origin xyz="0.0 -0.19688683106596772 0.0" rpy="0 0 0"/>
            <geometry>
                <box size="0.39377366213193543 0.39377366213193543 0.39377366213193543" />
            </geometry>
        </collision>
    </link>
    <joint name="Torso_limb3link0" type="revolute">
       <parent link="Torso"/>
       <child  link="limb3link0"/>
       <origin rpy="0 0 0" xyz="-1 -1 3.0" />
     <axis xyz="1 1 0"/>
       <limit effort="0.0" lower="-3.14159" upper="3.14159" velocity="0.0"/>
    </joint>
    <link name="limb3link0">
        <inertial>
            <origin xyz="-0.2736644494311915 -0.2736644494311915 0.0" rpy="0 0 0"/>
            <mass value="1" />
            <inertia ixx="100" ixy="0" ixz="0" iyy="100" iyz="0" izz="100" />
        </inertial>
        <visual>
            <origin xyz="-0.2736644494311915 -0.2736644494311915 0.0" rpy="0 0 0"/>
            <geometry>
                <box size="0.547328898862383 0.547328898862383 0.547328898862383" />
            </geometry>
            <material name="Cyan">
                <color rgba="0 1 1 1"/>
            </material>
        </visual>
        <collision>
            <origin xyz="-0.2736644494311915 -0.2736644494311915 0.0" rpy="0 0 0"/>
            <geometry>
                <box size="0.547328898862383 0.547328898862383 0.547328898862383" />
            </geometry>
        </collision>
    </link>
    <joint name="limb3link0_limb3link1" type="revolute">
       <parent link="limb3link0"/>
       <child  link="limb3link1"/>
       <origin rpy="0 0 0" xyz="0.0 -0.2736644494311915 0.0" />
     <axis xyz="1 0 0"/>
       <limit effort="0.0" lower="-3.14159" upper="3.14159" velocity="0.0"/>
    </joint>
    <link name="limb3link1">
        <inertial>
            <origin xyz="0.16810323933524254 0.0 0.0" rpy="0 0 0"/>
            <mass value="1" />
            <inertia ixx="100" ixy="0" ixz="0" iyy="100" iyz="0" izz="100" />
        </inertial>
        <visual>
            <origin xyz="0.16810323933524254 0.0 0.0" rpy="0 0 0"/>
            <geometry>
                <box size="0.3362064786704851 0.3362064786704851 0.3362064786704851" />
            </geometry>
            <material name="Cyan">
                <color rgba="0 1 1 1"/>
            </material>
        </visual>
        <collision>
            <origin xyz="0.16810323933524254 0.0 0.0" rpy="0 0 0"/>
            <geometry>
                <box size="0.3362064786704851 0.3362064786704851 0.3362064786704851" />
            </geometry>
        </collision>
    </link>
    <joint name="limb3link1_limb3link2" type="revolute">
       <parent link="limb3link1"/>
       <child  link="limb3link2"/>
       <origin rpy="0 0 0" xyz="0.16810323933524254 -0.16810323933524254 0.0" />
     <axis xyz="0 1 0"/>
       <limit effort="0.0" lower="-3.14159" upper="3.14159" velocity="0.0"/>
    </joint>
    <link name="limb3link2">
        <inertial>
            <origin xyz="0.0 -0.26786954496454096 0.0" rpy="0 0 0"/>
            <mass value="1" />
            <inertia ixx="100" ixy="0" ixz="0" iyy="100" iyz="0" izz="100" />
        </inertial>
        <visual>
            <origin xyz="0.0 -0.26786954496454096 0.0" rpy="0 0 0"/>
            <geometry>
                <box size="0.1985187761498 0.5357390899290819 0.5262749742979467" />
            </geometry>
            <material name="Green">
                <color rgba="0 1 0 1"/>
            </material>
        </visual>
        <collision>
            <origin xyz="0.0 -0.26786954496454096 0.0" rpy="0 0 0"/>
            <geometry>
                <box size="0.1985187761498 0.5357390899290819 0.5262749742979467" />
            </geometry>
        </collision>
    </link>
    <joint name="limb3link2_limb3link3" type="revolute">
       <parent link="limb3link2"/>
       <child  link="limb3link3"/>
       <origin rpy="0 0 0" xyz="0.0992593880749 -0.5357390899290819 0.0" />
     <axis xyz="1 1 0"/>
       <limit effort="0.0" lower="-3.14159" upper="3.14159" velocity="0.0"/>
    </joint>
    <link name="limb3link3">
        <inertial>
            <origin xyz="0.20127494426595943 -0.20127494426595943 0.0" rpy="0 0 0"/>
            <mass value="1" />
            <inertia ixx="100" ixy="0" ixz="0" iyy="100" iyz="0" izz="100" />
        </inertial>
        <visual>
            <origin xyz="0.20127494426595943 -0.20127494426595943 0.0" rpy="0 0 0"/>
            <geometry>
                <box size="0.40254988853191886 0.40254988853191886 0.40254988853191886" />
            </geometry>
            <material name="Green">
                <color rgba="0 1 0 1"/>
            </material>
        </visual>
        <collision>
            <origin xyz="0.20127494426595943 -0.20127494426595943 0.0" rpy="0 0 0"/>
            <geometry>
                <box size="0.40254988853191886 0.40254988853191886 0.40254988853191886" />
            </geometry>
        </collision>
    </link>
</robot>