<robot name = "robot">
    <link name="Torso">
        <inertial>
            <origin xyz="0 0 3" rpy="0 0 0"/>
            <mass value="1" />
            <inertia ixx="100" ixy="0" ixz="0" iyy="100" iyz="0" izz="100" />
        </inertial>
        <visual>
            <origin xyz="0 0 3" rpy="0 0 0"/>
            <geometry>
                <box size="2 2 1" />
            </geometry>
            <material name="Cyan">
                <color rgba="0 1 1 1"/>
            </material>
        </visual>
        <collision>
            <origin xyz="0 0 3" rpy="0 0 0"/>
            <geometry>
                <box size="2 2 1" />
            </geometry>
        </collision>
    </link>
    <joint name="Torso_limb0link0" type="revolute">
       <parent link="Torso"/>
       <child  link="limb0link0"/>
       <origin rpy="0 0 0" xyz="1 1 3.0" />
     <axis xyz="1 1 0"/>
       <limit effort="0.0" lower="-3.14159" upper="3.14159" velocity="0.0"/>
    </joint>
    <link name="limb0link0">
        <inertial>
            <origin xyz="0.13068369164321247 0.13068369164321247 0.0" rpy="0 0 0"/>
            <mass value="1" />
            <inertia ixx="100" ixy="0" ixz="0" iyy="100" iyz="0" izz="100" />
        </inertial>
        <visual>
            <origin xyz="0.13068369164321247 0.13068369164321247 0.0" rpy="0 0 0"/>
            <geometry>
                <box size="0.26136738328642495 0.26136738328642495 0.26136738328642495" />
            </geometry>
            <material name="Cyan">
                <color rgba="0 1 1 1"/>
            </material>
        </visual>
        <collision>
            <origin xyz="0.13068369164321247 0.13068369164321247 0.0" rpy="0 0 0"/>
            <geometry>
                <box size="0.26136738328642495 0.26136738328642495 0.26136738328642495" />
            </geometry>
        </collision>
    </link>
    <joint name="limb0link0_limb0link1" type="revolute">
       <parent link="limb0link0"/>
       <child  link="limb0link1"/>
       <origin rpy="0 0 0" xyz="0.26136738328642495 0.26136738328642495 0.0" />
     <axis xyz="1 1 0"/>
       <limit effort="0.0" lower="-3.14159" upper="3.14159" velocity="0.0"/>
    </joint>
    <link name="limb0link1">
        <inertial>
            <origin xyz="0.08578469478323716 0.08578469478323716 0.0" rpy="0 0 0"/>
            <mass value="1" />
            <inertia ixx="100" ixy="0" ixz="0" iyy="100" iyz="0" izz="100" />
        </inertial>
        <visual>
            <origin xyz="0.08578469478323716 0.08578469478323716 0.0" rpy="0 0 0"/>
            <geometry>
                <box size="0.17156938956647433 0.17156938956647433 0.17156938956647433" />
            </geometry>
            <material name="Cyan">
                <color rgba="0 1 1 1"/>
            </material>
        </visual>
        <collision>
            <origin xyz="0.08578469478323716 0.08578469478323716 0.0" rpy="0 0 0"/>
            <geometry>
                <box size="0.17156938956647433 0.17156938956647433 0.17156938956647433" />
            </geometry>
        </collision>
    </link>
    <joint name="limb0link1_limb0link2" type="revolute">
       <parent link="limb0link1"/>
       <child  link="limb0link2"/>
       <origin rpy="0 0 0" xyz="0.0 0.08578469478323716 0.0" />
     <axis xyz="1 0 0"/>
       <limit effort="0.0" lower="-3.14159" upper="3.14159" velocity="0.0"/>
    </joint>
    <link name="limb0link2">
        <inertial>
            <origin xyz="-0.3168879835574248 0.0 0.0" rpy="0 0 0"/>
            <mass value="1" />
            <inertia ixx="100" ixy="0" ixz="0" iyy="100" iyz="0" izz="100" />
        </inertial>
        <visual>
            <origin xyz="-0.3168879835574248 0.0 0.0" rpy="0 0 0"/>
            <geometry>
                <box size="0.6337759671148496 0.55297342257189 0.510654223001483" />
            </geometry>
            <material name="Green">
                <color rgba="0 1 0 1"/>
            </material>
        </visual>
        <collision>
            <origin xyz="-0.3168879835574248 0.0 0.0" rpy="0 0 0"/>
            <geometry>
                <box size="0.6337759671148496 0.55297342257189 0.510654223001483" />
            </geometry>
        </collision>
    </link>
    <joint name="limb0link2_limb0link3" type="revolute">
       <parent link="limb0link2"/>
       <child  link="limb0link3"/>
       <origin rpy="0 0 0" xyz="-0.6337759671148496 0.0 -0.2553271115007415" />
     <axis xyz="1 0 1"/>
       <limit effort="0.0" lower="-3.14159" upper="3.14159" velocity="0.0"/>
    </joint>
    <link name="limb0link3">
        <inertial>
            <origin xyz="-0.17532534817996998 0.0 -0.17532534817996998" rpy="0 0 0"/>
            <mass value="1" />
            <inertia ixx="100" ixy="0" ixz="0" iyy="100" iyz="0" izz="100" />
        </inertial>
        <visual>
            <origin xyz="-0.17532534817996998 0.0 -0.17532534817996998" rpy="0 0 0"/>
            <geometry>
                <box size="0.35065069635993995 0.35065069635993995 0.35065069635993995" />
            </geometry>
            <material name="Green">
                <color rgba="0 1 0 1"/>
            </material>
        </visual>
        <collision>
            <origin xyz="-0.17532534817996998 0.0 -0.17532534817996998" rpy="0 0 0"/>
            <geometry>
                <box size="0.35065069635993995 0.35065069635993995 0.35065069635993995" />
            </geometry>
        </collision>
    </link>
    <joint name="Torso_limb1link0" type="revolute">
       <parent link="Torso"/>
       <child  link="limb1link0"/>
       <origin rpy="0 0 0" xyz="1 -1 3.0" />
     <axis xyz="1 1 0"/>
       <limit effort="0.0" lower="-3.14159" upper="3.14159" velocity="0.0"/>
    </joint>
    <link name="limb1link0">
        <inertial>
            <origin xyz="0.42679331743669646 -0.42679331743669646 0.0" rpy="0 0 0"/>
            <mass value="1" />
            <inertia ixx="100" ixy="0" ixz="0" iyy="100" iyz="0" izz="100" />
        </inertial>
        <visual>
            <origin xyz="0.42679331743669646 -0.42679331743669646 0.0" rpy="0 0 0"/>
            <geometry>
                <box size="0.8535866348733929 0.8535866348733929 0.8535866348733929" />
            </geometry>
            <material name="Cyan">
                <color rgba="0 1 1 1"/>
            </material>
        </visual>
        <collision>
            <origin xyz="0.42679331743669646 -0.42679331743669646 0.0" rpy="0 0 0"/>
            <geometry>
                <box size="0.8535866348733929 0.8535866348733929 0.8535866348733929" />
            </geometry>
        </collision>
    </link>
    <joint name="limb1link0_limb1link1" type="revolute">
       <parent link="limb1link0"/>
       <child  link="limb1link1"/>
       <origin rpy="0 0 0" xyz="0.0 -0.8535866348733929 0.0" />
     <axis xyz="1 1 0"/>
       <limit effort="0.0" lower="-3.14159" upper="3.14159" velocity="0.0"/>
    </joint>
    <link name="limb1link1">
        <inertial>
            <origin xyz="-0.34577167872564935 -0.34577167872564935 0.0" rpy="0 0 0"/>
            <mass value="1" />
            <inertia ixx="100" ixy="0" ixz="0" iyy="100" iyz="0" izz="100" />
        </inertial>
        <visual>
            <origin xyz="-0.34577167872564935 -0.34577167872564935 0.0" rpy="0 0 0"/>
            <geometry>
                <box size="0.6915433574512987 0.6915433574512987 0.6915433574512987" />
            </geometry>
            <material name="Green">
                <color rgba="0 1 0 1"/>
            </material>
        </visual>
        <collision>
            <origin xyz="-0.34577167872564935 -0.34577167872564935 0.0" rpy="0 0 0"/>
            <geometry>
                <box size="0.6915433574512987 0.6915433574512987 0.6915433574512987" />
            </geometry>
        </collision>
    </link>
    <joint name="limb1link1_limb1link2" type="revolute">
       <parent link="limb1link1"/>
       <child  link="limb1link2"/>
       <origin rpy="0 0 0" xyz="-0.34577167872564935 -0.34577167872564935 -0.34577167872564935" />
     <axis xyz="0 0 1"/>
       <limit effort="0.0" lower="-3.14159" upper="3.14159" velocity="0.0"/>
    </joint>
    <link name="limb1link2">
        <inertial>
            <origin xyz="0.0 0.0 -0.0750115152545809" rpy="0 0 0"/>
            <mass value="1" />
            <inertia ixx="100" ixy="0" ixz="0" iyy="100" iyz="0" izz="100" />
        </inertial>
        <visual>
            <origin xyz="0.0 0.0 -0.0750115152545809" rpy="0 0 0"/>
            <geometry>
                <box size="0.1500230305091618 0.1500230305091618 0.1500230305091618" />
            </geometry>
            <material name="Green">
                <color rgba="0 1 0 1"/>
            </material>
        </visual>
        <collision>
            <origin xyz="0.0 0.0 -0.0750115152545809" rpy="0 0 0"/>
            <geometry>
                <box size="0.1500230305091618 0.1500230305091618 0.1500230305091618" />
            </geometry>
        </collision>
    </link>
    <joint name="Torso_limb2link0" type="revolute">
       <parent link="Torso"/>
       <child  link="limb2link0"/>
       <origin rpy="0 0 0" xyz="-1 1 3.0" />
     <axis xyz="1 1 0"/>
       <limit effort="0.0" lower="-3.14159" upper="3.14159" velocity="0.0"/>
    </joint>
    <link name="limb2link0">
        <inertial>
            <origin xyz="-0.13068369164321247 0.13068369164321247 0.0" rpy="0 0 0"/>
            <mass value="1" />
            <inertia ixx="100" ixy="0" ixz="0" iyy="100" iyz="0" izz="100" />
        </inertial>
        <visual>
            <origin xyz="-0.13068369164321247 0.13068369164321247 0.0" rpy="0 0 0"/>
            <geometry>
                <box size="0.26136738328642495 0.26136738328642495 0.26136738328642495" />
            </geometry>
            <material name="Cyan">
                <color rgba="0 1 1 1"/>
            </material>
        </visual>
        <collision>
            <origin xyz="-0.13068369164321247 0.13068369164321247 0.0" rpy="0 0 0"/>
            <geometry>
                <box size="0.26136738328642495 0.26136738328642495 0.26136738328642495" />
            </geometry>
        </collision>
    </link>
    <joint name="limb2link0_limb2link1" type="revolute">
       <parent link="limb2link0"/>
       <child  link="limb2link1"/>
       <origin rpy="0 0 0" xyz="-0.26136738328642495 0.26136738328642495 0.0" />
     <axis xyz="1 1 0"/>
       <limit effort="0.0" lower="-3.14159" upper="3.14159" velocity="0.0"/>
    </joint>
    <link name="limb2link1">
        <inertial>
            <origin xyz="-0.08578469478323716 0.08578469478323716 0.0" rpy="0 0 0"/>
            <mass value="1" />
            <inertia ixx="100" ixy="0" ixz="0" iyy="100" iyz="0" izz="100" />
        </inertial>
        <visual>
            <origin xyz="-0.08578469478323716 0.08578469478323716 0.0" rpy="0 0 0"/>
            <geometry>
                <box size="0.17156938956647433 0.17156938956647433 0.17156938956647433" />
            </geometry>
            <material name="Cyan">
                <color rgba="0 1 1 1"/>
            </material>
        </visual>
        <collision>
            <origin xyz="-0.08578469478323716 0.08578469478323716 0.0" rpy="0 0 0"/>
            <geometry>
                <box size="0.17156938956647433 0.17156938956647433 0.17156938956647433" />
            </geometry>
        </collision>
    </link>
    <joint name="limb2link1_limb2link2" type="revolute">
       <parent link="limb2link1"/>
       <child  link="limb2link2"/>
       <origin rpy="0 0 0" xyz="0.0 0.08578469478323716 0.0" />
     <axis xyz="1 0 0"/>
       <limit effort="0.0" lower="-3.14159" upper="3.14159" velocity="0.0"/>
    </joint>
    <link name="limb2link2">
        <inertial>
            <origin xyz="0.3168879835574248 0.0 0.0" rpy="0 0 0"/>
            <mass value="1" />
            <inertia ixx="100" ixy="0" ixz="0" iyy="100" iyz="0" izz="100" />
        </inertial>
        <visual>
            <origin xyz="0.3168879835574248 0.0 0.0" rpy="0 0 0"/>
            <geometry>
                <box size="0.6337759671148496 0.55297342257189 0.510654223001483" />
            </geometry>
            <material name="Green">
                <color rgba="0 1 0 1"/>
            </material>
        </visual>
        <collision>
            <origin xyz="0.3168879835574248 0.0 0.0" rpy="0 0 0"/>
            <geometry>
                <box size="0.6337759671148496 0.55297342257189 0.510654223001483" />
            </geometry>
        </collision>
    </link>
    <joint name="limb2link2_limb2link3" type="revolute">
       <parent link="limb2link2"/>
       <child  link="limb2link3"/>
       <origin rpy="0 0 0" xyz="0.6337759671148496 0.0 -0.2553271115007415" />
     <axis xyz="1 0 1"/>
       <limit effort="0.0" lower="-3.14159" upper="3.14159" velocity="0.0"/>
    </joint>
    <link name="limb2link3">
        <inertial>
            <origin xyz="0.17532534817996998 0.0 -0.17532534817996998" rpy="0 0 0"/>
            <mass value="1" />
            <inertia ixx="100" ixy="0" ixz="0" iyy="100" iyz="0" izz="100" />
        </inertial>
        <visual>
            <origin xyz="0.17532534817996998 0.0 -0.17532534817996998" rpy="0 0 0"/>
            <geometry>
                <box size="0.35065069635993995 0.35065069635993995 0.35065069635993995" />
            </geometry>
            <material name="Green">
                <color rgba="0 1 0 1"/>
            </material>
        </visual>
        <collision>
            <origin xyz="0.17532534817996998 0.0 -0.17532534817996998" rpy="0 0 0"/>
            <geometry>
                <box size="0.35065069635993995 0.35065069635993995 0.35065069635993995" />
            </geometry>
        </collision>
    </link>
    <joint name="Torso_limb3link0" type="revolute">
       <parent link="Torso"/>
       <child  link="limb3link0"/>
       <origin rpy="0 0 0" xyz="-1 -1 3.0" />
     <axis xyz="1 1 0"/>
       <limit effort="0.0" lower="-3.14159" upper="3.14159" velocity="0.0"/>
    </joint>
    <link name="limb3link0">
        <inertial>
            <origin xyz="-0.42679331743669646 -0.42679331743669646 0.0" rpy="0 0 0"/>
            <mass value="1" />
            <inertia ixx="100" ixy="0" ixz="0" iyy="100" iyz="0" izz="100" />
        </inertial>
        <visual>
            <origin xyz="-0.42679331743669646 -0.42679331743669646 0.0" rpy="0 0 0"/>
            <geometry>
                <box size="0.8535866348733929 0.8535866348733929 0.8535866348733929" />
            </geometry>
            <material name="Cyan">
                <color rgba="0 1 1 1"/>
            </material>
        </visual>
        <collision>
            <origin xyz="-0.42679331743669646 -0.42679331743669646 0.0" rpy="0 0 0"/>
            <geometry>
                <box size="0.8535866348733929 0.8535866348733929 0.8535866348733929" />
            </geometry>
        </collision>
    </link>
    <joint name="limb3link0_limb3link1" type="revolute">
       <parent link="limb3link0"/>
       <child  link="limb3link1"/>
       <origin rpy="0 0 0" xyz="0.0 -0.8535866348733929 0.0" />
     <axis xyz="1 1 0"/>
       <limit effort="0.0" lower="-3.14159" upper="3.14159" velocity="0.0"/>
    </joint>
    <link name="limb3link1">
        <inertial>
            <origin xyz="0.34577167872564935 -0.34577167872564935 0.0" rpy="0 0 0"/>
            <mass value="1" />
            <inertia ixx="100" ixy="0" ixz="0" iyy="100" iyz="0" izz="100" />
        </inertial>
        <visual>
            <origin xyz="0.34577167872564935 -0.34577167872564935 0.0" rpy="0 0 0"/>
            <geometry>
                <box size="0.6915433574512987 0.6915433574512987 0.6915433574512987" />
            </geometry>
            <material name="Green">
                <color rgba="0 1 0 1"/>
            </material>
        </visual>
        <collision>
            <origin xyz="0.34577167872564935 -0.34577167872564935 0.0" rpy="0 0 0"/>
            <geometry>
                <box size="0.6915433574512987 0.6915433574512987 0.6915433574512987" />
            </geometry>
        </collision>
    </link>
    <joint name="limb3link1_limb3link2" type="revolute">
       <parent link="limb3link1"/>
       <child  link="limb3link2"/>
       <origin rpy="0 0 0" xyz="0.34577167872564935 -0.34577167872564935 -0.34577167872564935" />
     <axis xyz="0 0 1"/>
       <limit effort="0.0" lower="-3.14159" upper="3.14159" velocity="0.0"/>
    </joint>
    <link name="limb3link2">
        <inertial>
            <origin xyz="0.0 0.0 -0.0750115152545809" rpy="0 0 0"/>
            <mass value="1" />
            <inertia ixx="100" ixy="0" ixz="0" iyy="100" iyz="0" izz="100" />
        </inertial>
        <visual>
            <origin xyz="0.0 0.0 -0.0750115152545809" rpy="0 0 0"/>
            <geometry>
                <box size="0.1500230305091618 0.1500230305091618 0.1500230305091618" />
            </geometry>
            <material name="Green">
                <color rgba="0 1 0 1"/>
            </material>
        </visual>
        <collision>
            <origin xyz="0.0 0.0 -0.0750115152545809" rpy="0 0 0"/>
            <geometry>
                <box size="0.1500230305091618 0.1500230305091618 0.1500230305091618" />
            </geometry>
        </collision>
    </link>
</robot>