<robot name = "robot">
    <link name="Torso">
        <inertial>
            <origin xyz="0 0 3" rpy="0 0 0"/>
            <mass value="1" />
            <inertia ixx="100" ixy="0" ixz="0" iyy="100" iyz="0" izz="100" />
        </inertial>
        <visual>
            <origin xyz="0 0 3" rpy="0 0 0"/>
            <geometry>
                <box size="2 2 1" />
            </geometry>
            <material name="Cyan">
                <color rgba="0 1 1 1"/>
            </material>
        </visual>
        <collision>
            <origin xyz="0 0 3" rpy="0 0 0"/>
            <geometry>
                <box size="2 2 1" />
            </geometry>
        </collision>
    </link>
    <joint name="Torso_limb0link0" type="revolute">
       <parent link="Torso"/>
       <child  link="limb0link0"/>
       <origin rpy="0 0 0" xyz="1 1 3.0" />
     <axis xyz="1 1 0"/>
       <limit effort="0.0" lower="-3.14159" upper="3.14159" velocity="0.0"/>
    </joint>
    <link name="limb0link0">
        <inertial>
            <origin xyz="0.22647597346903275 0.22647597346903275 0.0" rpy="0 0 0"/>
            <mass value="1" />
            <inertia ixx="100" ixy="0" ixz="0" iyy="100" iyz="0" izz="100" />
        </inertial>
        <visual>
            <origin xyz="0.22647597346903275 0.22647597346903275 0.0" rpy="0 0 0"/>
            <geometry>
                <box size="0.4529519469380655 0.4529519469380655 0.4529519469380655" />
            </geometry>
            <material name="Green">
                <color rgba="0 1 0 1"/>
            </material>
        </visual>
        <collision>
            <origin xyz="0.22647597346903275 0.22647597346903275 0.0" rpy="0 0 0"/>
            <geometry>
                <box size="0.4529519469380655 0.4529519469380655 0.4529519469380655" />
            </geometry>
        </collision>
    </link>
    <joint name="limb0link0_limb0link1" type="revolute">
       <parent link="limb0link0"/>
       <child  link="limb0link1"/>
       <origin rpy="0 0 0" xyz="0.22647597346903275 0.0 0.0" />
     <axis xyz="0 1 0"/>
       <limit effort="0.0" lower="-3.14159" upper="3.14159" velocity="0.0"/>
    </joint>
    <link name="limb0link1">
        <inertial>
            <origin xyz="0.0 -0.3992398949886218 0.0" rpy="0 0 0"/>
            <mass value="1" />
            <inertia ixx="100" ixy="0" ixz="0" iyy="100" iyz="0" izz="100" />
        </inertial>
        <visual>
            <origin xyz="0.0 -0.3992398949886218 0.0" rpy="0 0 0"/>
            <geometry>
                <box size="0.7984797899772436 0.7984797899772436 0.7984797899772436" />
            </geometry>
            <material name="Green">
                <color rgba="0 1 0 1"/>
            </material>
        </visual>
        <collision>
            <origin xyz="0.0 -0.3992398949886218 0.0" rpy="0 0 0"/>
            <geometry>
                <box size="0.7984797899772436 0.7984797899772436 0.7984797899772436" />
            </geometry>
        </collision>
    </link>
    <joint name="Torso_limb1link0" type="revolute">
       <parent link="Torso"/>
       <child  link="limb1link0"/>
       <origin rpy="0 0 0" xyz="1 -1 3.0" />
     <axis xyz="1 1 0"/>
       <limit effort="0.0" lower="-3.14159" upper="3.14159" velocity="0.0"/>
    </joint>
    <link name="limb1link0">
        <inertial>
            <origin xyz="0.3887892031352115 -0.3887892031352115 0.0" rpy="0 0 0"/>
            <mass value="1" />
            <inertia ixx="100" ixy="0" ixz="0" iyy="100" iyz="0" izz="100" />
        </inertial>
        <visual>
            <origin xyz="0.3887892031352115 -0.3887892031352115 0.0" rpy="0 0 0"/>
            <geometry>
                <box size="0.777578406270423 0.777578406270423 0.777578406270423" />
            </geometry>
            <material name="Cyan">
                <color rgba="0 1 1 1"/>
            </material>
        </visual>
        <collision>
            <origin xyz="0.3887892031352115 -0.3887892031352115 0.0" rpy="0 0 0"/>
            <geometry>
                <box size="0.777578406270423 0.777578406270423 0.777578406270423" />
            </geometry>
        </collision>
    </link>
    <joint name="limb1link0_limb1link1" type="revolute">
       <parent link="limb1link0"/>
       <child  link="limb1link1"/>
       <origin rpy="0 0 0" xyz="0.0 -0.777578406270423 0.0" />
     <axis xyz="1 1 0"/>
       <limit effort="0.0" lower="-3.14159" upper="3.14159" velocity="0.0"/>
    </joint>
    <link name="limb1link1">
        <inertial>
            <origin xyz="-0.36863820322154517 -0.36863820322154517 0.0" rpy="0 0 0"/>
            <mass value="1" />
            <inertia ixx="100" ixy="0" ixz="0" iyy="100" iyz="0" izz="100" />
        </inertial>
        <visual>
            <origin xyz="-0.36863820322154517 -0.36863820322154517 0.0" rpy="0 0 0"/>
            <geometry>
                <box size="0.7372764064430903 0.7372764064430903 0.7372764064430903" />
            </geometry>
            <material name="Cyan">
                <color rgba="0 1 1 1"/>
            </material>
        </visual>
        <collision>
            <origin xyz="-0.36863820322154517 -0.36863820322154517 0.0" rpy="0 0 0"/>
            <geometry>
                <box size="0.7372764064430903 0.7372764064430903 0.7372764064430903" />
            </geometry>
        </collision>
    </link>
    <joint name="limb1link1_limb1link2" type="revolute">
       <parent link="limb1link1"/>
       <child  link="limb1link2"/>
       <origin rpy="0 0 0" xyz="-0.36863820322154517 -0.7372764064430903 0.0" />
     <axis xyz="0 1 0"/>
       <limit effort="0.0" lower="-3.14159" upper="3.14159" velocity="0.0"/>
    </joint>
    <link name="limb1link2">
        <inertial>
            <origin xyz="0.0 -0.29422730380974343 0.0" rpy="0 0 0"/>
            <mass value="1" />
            <inertia ixx="100" ixy="0" ixz="0" iyy="100" iyz="0" izz="100" />
        </inertial>
        <visual>
            <origin xyz="0.0 -0.29422730380974343 0.0" rpy="0 0 0"/>
            <geometry>
                <box size="0.5884546076194869 0.5884546076194869 0.5884546076194869" />
            </geometry>
            <material name="Green">
                <color rgba="0 1 0 1"/>
            </material>
        </visual>
        <collision>
            <origin xyz="0.0 -0.29422730380974343 0.0" rpy="0 0 0"/>
            <geometry>
                <box size="0.5884546076194869 0.5884546076194869 0.5884546076194869" />
            </geometry>
        </collision>
    </link>
    <joint name="limb1link2_limb1link3" type="revolute">
       <parent link="limb1link2"/>
       <child  link="limb1link3"/>
       <origin rpy="0 0 0" xyz="0.0 -0.5884546076194869 0.0" />
     <axis xyz="0 1 0"/>
       <limit effort="0.0" lower="-3.14159" upper="3.14159" velocity="0.0"/>
    </joint>
    <link name="limb1link3">
        <inertial>
            <origin xyz="0.0 -0.24802191627491493 0.0" rpy="0 0 0"/>
            <mass value="1" />
            <inertia ixx="100" ixy="0" ixz="0" iyy="100" iyz="0" izz="100" />
        </inertial>
        <visual>
            <origin xyz="0.0 -0.24802191627491493 0.0" rpy="0 0 0"/>
            <geometry>
                <box size="0.35504341721562277 0.49604383254982987 0.16170559641691742" />
            </geometry>
            <material name="Green">
                <color rgba="0 1 0 1"/>
            </material>
        </visual>
        <collision>
            <origin xyz="0.0 -0.24802191627491493 0.0" rpy="0 0 0"/>
            <geometry>
                <box size="0.35504341721562277 0.49604383254982987 0.16170559641691742" />
            </geometry>
        </collision>
    </link>
    <joint name="Torso_limb2link0" type="revolute">
       <parent link="Torso"/>
       <child  link="limb2link0"/>
       <origin rpy="0 0 0" xyz="-1 1 3.0" />
     <axis xyz="1 1 0"/>
       <limit effort="0.0" lower="-3.14159" upper="3.14159" velocity="0.0"/>
    </joint>
    <link name="limb2link0">
        <inertial>
            <origin xyz="-0.22647597346903275 0.22647597346903275 0.0" rpy="0 0 0"/>
            <mass value="1" />
            <inertia ixx="100" ixy="0" ixz="0" iyy="100" iyz="0" izz="100" />
        </inertial>
        <visual>
            <origin xyz="-0.22647597346903275 0.22647597346903275 0.0" rpy="0 0 0"/>
            <geometry>
                <box size="0.4529519469380655 0.4529519469380655 0.4529519469380655" />
            </geometry>
            <material name="Green">
                <color rgba="0 1 0 1"/>
            </material>
        </visual>
        <collision>
            <origin xyz="-0.22647597346903275 0.22647597346903275 0.0" rpy="0 0 0"/>
            <geometry>
                <box size="0.4529519469380655 0.4529519469380655 0.4529519469380655" />
            </geometry>
        </collision>
    </link>
    <joint name="limb2link0_limb2link1" type="revolute">
       <parent link="limb2link0"/>
       <child  link="limb2link1"/>
       <origin rpy="0 0 0" xyz="-0.22647597346903275 0.0 0.0" />
     <axis xyz="0 1 0"/>
       <limit effort="0.0" lower="-3.14159" upper="3.14159" velocity="0.0"/>
    </joint>
    <link name="limb2link1">
        <inertial>
            <origin xyz="0.0 -0.3992398949886218 0.0" rpy="0 0 0"/>
            <mass value="1" />
            <inertia ixx="100" ixy="0" ixz="0" iyy="100" iyz="0" izz="100" />
        </inertial>
        <visual>
            <origin xyz="0.0 -0.3992398949886218 0.0" rpy="0 0 0"/>
            <geometry>
                <box size="0.7984797899772436 0.7984797899772436 0.7984797899772436" />
            </geometry>
            <material name="Green">
                <color rgba="0 1 0 1"/>
            </material>
        </visual>
        <collision>
            <origin xyz="0.0 -0.3992398949886218 0.0" rpy="0 0 0"/>
            <geometry>
                <box size="0.7984797899772436 0.7984797899772436 0.7984797899772436" />
            </geometry>
        </collision>
    </link>
    <joint name="Torso_limb3link0" type="revolute">
       <parent link="Torso"/>
       <child  link="limb3link0"/>
       <origin rpy="0 0 0" xyz="-1 -1 3.0" />
     <axis xyz="1 1 0"/>
       <limit effort="0.0" lower="-3.14159" upper="3.14159" velocity="0.0"/>
    </joint>
    <link name="limb3link0">
        <inertial>
            <origin xyz="-0.3887892031352115 -0.3887892031352115 0.0" rpy="0 0 0"/>
            <mass value="1" />
            <inertia ixx="100" ixy="0" ixz="0" iyy="100" iyz="0" izz="100" />
        </inertial>
        <visual>
            <origin xyz="-0.3887892031352115 -0.3887892031352115 0.0" rpy="0 0 0"/>
            <geometry>
                <box size="0.777578406270423 0.777578406270423 0.777578406270423" />
            </geometry>
            <material name="Cyan">
                <color rgba="0 1 1 1"/>
            </material>
        </visual>
        <collision>
            <origin xyz="-0.3887892031352115 -0.3887892031352115 0.0" rpy="0 0 0"/>
            <geometry>
                <box size="0.777578406270423 0.777578406270423 0.777578406270423" />
            </geometry>
        </collision>
    </link>
    <joint name="limb3link0_limb3link1" type="revolute">
       <parent link="limb3link0"/>
       <child  link="limb3link1"/>
       <origin rpy="0 0 0" xyz="0.0 -0.777578406270423 0.0" />
     <axis xyz="1 1 0"/>
       <limit effort="0.0" lower="-3.14159" upper="3.14159" velocity="0.0"/>
    </joint>
    <link name="limb3link1">
        <inertial>
            <origin xyz="0.36863820322154517 -0.36863820322154517 0.0" rpy="0 0 0"/>
            <mass value="1" />
            <inertia ixx="100" ixy="0" ixz="0" iyy="100" iyz="0" izz="100" />
        </inertial>
        <visual>
            <origin xyz="0.36863820322154517 -0.36863820322154517 0.0" rpy="0 0 0"/>
            <geometry>
                <box size="0.7372764064430903 0.7372764064430903 0.7372764064430903" />
            </geometry>
            <material name="Cyan">
                <color rgba="0 1 1 1"/>
            </material>
        </visual>
        <collision>
            <origin xyz="0.36863820322154517 -0.36863820322154517 0.0" rpy="0 0 0"/>
            <geometry>
                <box size="0.7372764064430903 0.7372764064430903 0.7372764064430903" />
            </geometry>
        </collision>
    </link>
    <joint name="limb3link1_limb3link2" type="revolute">
       <parent link="limb3link1"/>
       <child  link="limb3link2"/>
       <origin rpy="0 0 0" xyz="0.36863820322154517 -0.7372764064430903 0.0" />
     <axis xyz="0 1 0"/>
       <limit effort="0.0" lower="-3.14159" upper="3.14159" velocity="0.0"/>
    </joint>
    <link name="limb3link2">
        <inertial>
            <origin xyz="0.0 -0.29422730380974343 0.0" rpy="0 0 0"/>
            <mass value="1" />
            <inertia ixx="100" ixy="0" ixz="0" iyy="100" iyz="0" izz="100" />
        </inertial>
        <visual>
            <origin xyz="0.0 -0.29422730380974343 0.0" rpy="0 0 0"/>
            <geometry>
                <box size="0.5884546076194869 0.5884546076194869 0.5884546076194869" />
            </geometry>
            <material name="Green">
                <color rgba="0 1 0 1"/>
            </material>
        </visual>
        <collision>
            <origin xyz="0.0 -0.29422730380974343 0.0" rpy="0 0 0"/>
            <geometry>
                <box size="0.5884546076194869 0.5884546076194869 0.5884546076194869" />
            </geometry>
        </collision>
    </link>
    <joint name="limb3link2_limb3link3" type="revolute">
       <parent link="limb3link2"/>
       <child  link="limb3link3"/>
       <origin rpy="0 0 0" xyz="0.0 -0.5884546076194869 0.0" />
     <axis xyz="0 1 0"/>
       <limit effort="0.0" lower="-3.14159" upper="3.14159" velocity="0.0"/>
    </joint>
    <link name="limb3link3">
        <inertial>
            <origin xyz="0.0 -0.24802191627491493 0.0" rpy="0 0 0"/>
            <mass value="1" />
            <inertia ixx="100" ixy="0" ixz="0" iyy="100" iyz="0" izz="100" />
        </inertial>
        <visual>
            <origin xyz="0.0 -0.24802191627491493 0.0" rpy="0 0 0"/>
            <geometry>
                <box size="0.35504341721562277 0.49604383254982987 0.16170559641691742" />
            </geometry>
            <material name="Green">
                <color rgba="0 1 0 1"/>
            </material>
        </visual>
        <collision>
            <origin xyz="0.0 -0.24802191627491493 0.0" rpy="0 0 0"/>
            <geometry>
                <box size="0.35504341721562277 0.49604383254982987 0.16170559641691742" />
            </geometry>
        </collision>
    </link>
</robot>