<robot name = "robot">
    <link name="Torso">
        <inertial>
            <origin xyz="0 0 3" rpy="0 0 0"/>
            <mass value="1" />
            <inertia ixx="100" ixy="0" ixz="0" iyy="100" iyz="0" izz="100" />
        </inertial>
        <visual>
            <origin xyz="0 0 3" rpy="0 0 0"/>
            <geometry>
                <box size="2 2 1" />
            </geometry>
            <material name="Cyan">
                <color rgba="0 1 1 1"/>
            </material>
        </visual>
        <collision>
            <origin xyz="0 0 3" rpy="0 0 0"/>
            <geometry>
                <box size="2 2 1" />
            </geometry>
        </collision>
    </link>
    <joint name="Torso_limb0link0" type="revolute">
       <parent link="Torso"/>
       <child  link="limb0link0"/>
       <origin rpy="0 0 0" xyz="1 1 3.0" />
     <axis xyz="1 1 0"/>
       <limit effort="0.0" lower="-3.14159" upper="3.14159" velocity="0.0"/>
    </joint>
    <link name="limb0link0">
        <inertial>
            <origin xyz="0.2858346771158481 0.2858346771158481 0.0" rpy="0 0 0"/>
            <mass value="1" />
            <inertia ixx="100" ixy="0" ixz="0" iyy="100" iyz="0" izz="100" />
        </inertial>
        <visual>
            <origin xyz="0.2858346771158481 0.2858346771158481 0.0" rpy="0 0 0"/>
            <geometry>
                <box size="0.5716693542316962 0.5716693542316962 0.5716693542316962" />
            </geometry>
            <material name="Cyan">
                <color rgba="0 1 1 1"/>
            </material>
        </visual>
        <collision>
            <origin xyz="0.2858346771158481 0.2858346771158481 0.0" rpy="0 0 0"/>
            <geometry>
                <box size="0.5716693542316962 0.5716693542316962 0.5716693542316962" />
            </geometry>
        </collision>
    </link>
    <joint name="limb0link0_limb0link1" type="revolute">
       <parent link="limb0link0"/>
       <child  link="limb0link1"/>
       <origin rpy="0 0 0" xyz="0.0 0.2858346771158481 -0.2858346771158481" />
     <axis xyz="1 0 1"/>
       <limit effort="0.0" lower="-3.14159" upper="3.14159" velocity="0.0"/>
    </joint>
    <link name="limb0link1">
        <inertial>
            <origin xyz="-0.36947994838848053 0.0 -0.19761259923652585" rpy="0 0 0"/>
            <mass value="1" />
            <inertia ixx="100" ixy="0" ixz="0" iyy="100" iyz="0" izz="100" />
        </inertial>
        <visual>
            <origin xyz="-0.36947994838848053 0.0 -0.19761259923652585" rpy="0 0 0"/>
            <geometry>
                <box size="0.7389598967769611 0.778924284400638 0.3952251984730517" />
            </geometry>
            <material name="Green">
                <color rgba="0 1 0 1"/>
            </material>
        </visual>
        <collision>
            <origin xyz="-0.36947994838848053 0.0 -0.19761259923652585" rpy="0 0 0"/>
            <geometry>
                <box size="0.7389598967769611 0.778924284400638 0.3952251984730517" />
            </geometry>
        </collision>
    </link>
    <joint name="limb0link1_limb0link2" type="revolute">
       <parent link="limb0link1"/>
       <child  link="limb0link2"/>
       <origin rpy="0 0 0" xyz="-0.7389598967769611 -0.389462142200319 -0.19761259923652585" />
     <axis xyz="1 1 0"/>
       <limit effort="0.0" lower="-3.14159" upper="3.14159" velocity="0.0"/>
    </joint>
    <link name="limb0link2">
        <inertial>
            <origin xyz="-0.1745782612624765 -0.19924041033280918 0.0" rpy="0 0 0"/>
            <mass value="1" />
            <inertia ixx="100" ixy="0" ixz="0" iyy="100" iyz="0" izz="100" />
        </inertial>
        <visual>
            <origin xyz="-0.1745782612624765 -0.19924041033280918 0.0" rpy="0 0 0"/>
            <geometry>
                <box size="0.349156522524953 0.39848082066561835 0.5022308798082599" />
            </geometry>
            <material name="Green">
                <color rgba="0 1 0 1"/>
            </material>
        </visual>
        <collision>
            <origin xyz="-0.1745782612624765 -0.19924041033280918 0.0" rpy="0 0 0"/>
            <geometry>
                <box size="0.349156522524953 0.39848082066561835 0.5022308798082599" />
            </geometry>
        </collision>
    </link>
    <joint name="Torso_limb1link0" type="revolute">
       <parent link="Torso"/>
       <child  link="limb1link0"/>
       <origin rpy="0 0 0" xyz="1 -1 3.0" />
     <axis xyz="1 1 0"/>
       <limit effort="0.0" lower="-3.14159" upper="3.14159" velocity="0.0"/>
    </joint>
    <link name="limb1link0">
        <inertial>
            <origin xyz="0.3926431610214186 -0.3926431610214186 0.0" rpy="0 0 0"/>
            <mass value="1" />
            <inertia ixx="100" ixy="0" ixz="0" iyy="100" iyz="0" izz="100" />
        </inertial>
        <visual>
            <origin xyz="0.3926431610214186 -0.3926431610214186 0.0" rpy="0 0 0"/>
            <geometry>
                <box size="0.7852863220428372 0.7852863220428372 0.7852863220428372" />
            </geometry>
            <material name="Green">
                <color rgba="0 1 0 1"/>
            </material>
        </visual>
        <collision>
            <origin xyz="0.3926431610214186 -0.3926431610214186 0.0" rpy="0 0 0"/>
            <geometry>
                <box size="0.7852863220428372 0.7852863220428372 0.7852863220428372" />
            </geometry>
        </collision>
    </link>
    <joint name="limb1link0_limb1link1" type="revolute">
       <parent link="limb1link0"/>
       <child  link="limb1link1"/>
       <origin rpy="0 0 0" xyz="0.0 -0.3926431610214186 -0.3926431610214186" />
     <axis xyz="1 0 1"/>
       <limit effort="0.0" lower="-3.14159" upper="3.14159" velocity="0.0"/>
    </joint>
    <link name="limb1link1">
        <inertial>
            <origin xyz="-0.2796789882309952 0.0 -0.2796789882309952" rpy="0 0 0"/>
            <mass value="1" />
            <inertia ixx="100" ixy="0" ixz="0" iyy="100" iyz="0" izz="100" />
        </inertial>
        <visual>
            <origin xyz="-0.2796789882309952 0.0 -0.2796789882309952" rpy="0 0 0"/>
            <geometry>
                <box size="0.5593579764619904 0.5593579764619904 0.5593579764619904" />
            </geometry>
            <material name="Green">
                <color rgba="0 1 0 1"/>
            </material>
        </visual>
        <collision>
            <origin xyz="-0.2796789882309952 0.0 -0.2796789882309952" rpy="0 0 0"/>
            <geometry>
                <box size="0.5593579764619904 0.5593579764619904 0.5593579764619904" />
            </geometry>
        </collision>
    </link>
    <joint name="Torso_limb2link0" type="revolute">
       <parent link="Torso"/>
       <child  link="limb2link0"/>
       <origin rpy="0 0 0" xyz="-1 1 3.0" />
     <axis xyz="1 1 0"/>
       <limit effort="0.0" lower="-3.14159" upper="3.14159" velocity="0.0"/>
    </joint>
    <link name="limb2link0">
        <inertial>
            <origin xyz="-0.2858346771158481 0.2858346771158481 0.0" rpy="0 0 0"/>
            <mass value="1" />
            <inertia ixx="100" ixy="0" ixz="0" iyy="100" iyz="0" izz="100" />
        </inertial>
        <visual>
            <origin xyz="-0.2858346771158481 0.2858346771158481 0.0" rpy="0 0 0"/>
            <geometry>
                <box size="0.5716693542316962 0.5716693542316962 0.5716693542316962" />
            </geometry>
            <material name="Cyan">
                <color rgba="0 1 1 1"/>
            </material>
        </visual>
        <collision>
            <origin xyz="-0.2858346771158481 0.2858346771158481 0.0" rpy="0 0 0"/>
            <geometry>
                <box size="0.5716693542316962 0.5716693542316962 0.5716693542316962" />
            </geometry>
        </collision>
    </link>
    <joint name="limb2link0_limb2link1" type="revolute">
       <parent link="limb2link0"/>
       <child  link="limb2link1"/>
       <origin rpy="0 0 0" xyz="0.0 0.2858346771158481 -0.2858346771158481" />
     <axis xyz="1 0 1"/>
       <limit effort="0.0" lower="-3.14159" upper="3.14159" velocity="0.0"/>
    </joint>
    <link name="limb2link1">
        <inertial>
            <origin xyz="0.36947994838848053 0.0 -0.19761259923652585" rpy="0 0 0"/>
            <mass value="1" />
            <inertia ixx="100" ixy="0" ixz="0" iyy="100" iyz="0" izz="100" />
        </inertial>
        <visual>
            <origin xyz="0.36947994838848053 0.0 -0.19761259923652585" rpy="0 0 0"/>
            <geometry>
                <box size="0.7389598967769611 0.778924284400638 0.3952251984730517" />
            </geometry>
            <material name="Green">
                <color rgba="0 1 0 1"/>
            </material>
        </visual>
        <collision>
            <origin xyz="0.36947994838848053 0.0 -0.19761259923652585" rpy="0 0 0"/>
            <geometry>
                <box size="0.7389598967769611 0.778924284400638 0.3952251984730517" />
            </geometry>
        </collision>
    </link>
    <joint name="limb2link1_limb2link2" type="revolute">
       <parent link="limb2link1"/>
       <child  link="limb2link2"/>
       <origin rpy="0 0 0" xyz="0.7389598967769611 -0.389462142200319 -0.19761259923652585" />
     <axis xyz="1 1 0"/>
       <limit effort="0.0" lower="-3.14159" upper="3.14159" velocity="0.0"/>
    </joint>
    <link name="limb2link2">
        <inertial>
            <origin xyz="0.1745782612624765 -0.19924041033280918 0.0" rpy="0 0 0"/>
            <mass value="1" />
            <inertia ixx="100" ixy="0" ixz="0" iyy="100" iyz="0" izz="100" />
        </inertial>
        <visual>
            <origin xyz="0.1745782612624765 -0.19924041033280918 0.0" rpy="0 0 0"/>
            <geometry>
                <box size="0.349156522524953 0.39848082066561835 0.5022308798082599" />
            </geometry>
            <material name="Green">
                <color rgba="0 1 0 1"/>
            </material>
        </visual>
        <collision>
            <origin xyz="0.1745782612624765 -0.19924041033280918 0.0" rpy="0 0 0"/>
            <geometry>
                <box size="0.349156522524953 0.39848082066561835 0.5022308798082599" />
            </geometry>
        </collision>
    </link>
    <joint name="Torso_limb3link0" type="revolute">
       <parent link="Torso"/>
       <child  link="limb3link0"/>
       <origin rpy="0 0 0" xyz="-1 -1 3.0" />
     <axis xyz="1 1 0"/>
       <limit effort="0.0" lower="-3.14159" upper="3.14159" velocity="0.0"/>
    </joint>
    <link name="limb3link0">
        <inertial>
            <origin xyz="-0.3926431610214186 -0.3926431610214186 0.0" rpy="0 0 0"/>
            <mass value="1" />
            <inertia ixx="100" ixy="0" ixz="0" iyy="100" iyz="0" izz="100" />
        </inertial>
        <visual>
            <origin xyz="-0.3926431610214186 -0.3926431610214186 0.0" rpy="0 0 0"/>
            <geometry>
                <box size="0.7852863220428372 0.7852863220428372 0.7852863220428372" />
            </geometry>
            <material name="Green">
                <color rgba="0 1 0 1"/>
            </material>
        </visual>
        <collision>
            <origin xyz="-0.3926431610214186 -0.3926431610214186 0.0" rpy="0 0 0"/>
            <geometry>
                <box size="0.7852863220428372 0.7852863220428372 0.7852863220428372" />
            </geometry>
        </collision>
    </link>
    <joint name="limb3link0_limb3link1" type="revolute">
       <parent link="limb3link0"/>
       <child  link="limb3link1"/>
       <origin rpy="0 0 0" xyz="0.0 -0.3926431610214186 -0.3926431610214186" />
     <axis xyz="1 0 1"/>
       <limit effort="0.0" lower="-3.14159" upper="3.14159" velocity="0.0"/>
    </joint>
    <link name="limb3link1">
        <inertial>
            <origin xyz="0.2796789882309952 0.0 -0.2796789882309952" rpy="0 0 0"/>
            <mass value="1" />
            <inertia ixx="100" ixy="0" ixz="0" iyy="100" iyz="0" izz="100" />
        </inertial>
        <visual>
            <origin xyz="0.2796789882309952 0.0 -0.2796789882309952" rpy="0 0 0"/>
            <geometry>
                <box size="0.5593579764619904 0.5593579764619904 0.5593579764619904" />
            </geometry>
            <material name="Green">
                <color rgba="0 1 0 1"/>
            </material>
        </visual>
        <collision>
            <origin xyz="0.2796789882309952 0.0 -0.2796789882309952" rpy="0 0 0"/>
            <geometry>
                <box size="0.5593579764619904 0.5593579764619904 0.5593579764619904" />
            </geometry>
        </collision>
    </link>
</robot>