<robot name = "robot">
    <link name="Torso">
        <inertial>
            <origin xyz="0 0 3" rpy="0 0 0"/>
            <mass value="1" />
            <inertia ixx="100" ixy="0" ixz="0" iyy="100" iyz="0" izz="100" />
        </inertial>
        <visual>
            <origin xyz="0 0 3" rpy="0 0 0"/>
            <geometry>
                <box size="2 2 1" />
            </geometry>
            <material name="Cyan">
                <color rgba="0 1 1 1"/>
            </material>
        </visual>
        <collision>
            <origin xyz="0 0 3" rpy="0 0 0"/>
            <geometry>
                <box size="2 2 1" />
            </geometry>
        </collision>
    </link>
    <joint name="Torso_limb0link0" type="revolute">
       <parent link="Torso"/>
       <child  link="limb0link0"/>
       <origin rpy="0 0 0" xyz="1 1 3.0" />
     <axis xyz="1 1 0"/>
       <limit effort="0.0" lower="-3.14159" upper="3.14159" velocity="0.0"/>
    </joint>
    <link name="limb0link0">
        <inertial>
            <origin xyz="0.15640129557128957 0.15640129557128957 0.0" rpy="0 0 0"/>
            <mass value="1" />
            <inertia ixx="100" ixy="0" ixz="0" iyy="100" iyz="0" izz="100" />
        </inertial>
        <visual>
            <origin xyz="0.15640129557128957 0.15640129557128957 0.0" rpy="0 0 0"/>
            <geometry>
                <box size="0.31280259114257913 0.31280259114257913 0.31280259114257913" />
            </geometry>
            <material name="Cyan">
                <color rgba="0 1 1 1"/>
            </material>
        </visual>
        <collision>
            <origin xyz="0.15640129557128957 0.15640129557128957 0.0" rpy="0 0 0"/>
            <geometry>
                <box size="0.31280259114257913 0.31280259114257913 0.31280259114257913" />
            </geometry>
        </collision>
    </link>
    <joint name="limb0link0_limb0link1" type="revolute">
       <parent link="limb0link0"/>
       <child  link="limb0link1"/>
       <origin rpy="0 0 0" xyz="0.15640129557128957 0.0 -0.15640129557128957" />
     <axis xyz="0 1 1"/>
       <limit effort="0.0" lower="-3.14159" upper="3.14159" velocity="0.0"/>
    </joint>
    <link name="limb0link1">
        <inertial>
            <origin xyz="0.0 -0.33631463164746167 -0.33631463164746167" rpy="0 0 0"/>
            <mass value="1" />
            <inertia ixx="100" ixy="0" ixz="0" iyy="100" iyz="0" izz="100" />
        </inertial>
        <visual>
            <origin xyz="0.0 -0.33631463164746167 -0.33631463164746167" rpy="0 0 0"/>
            <geometry>
                <box size="0.6726292632949233 0.6726292632949233 0.6726292632949233" />
            </geometry>
            <material name="Green">
                <color rgba="0 1 0 1"/>
            </material>
        </visual>
        <collision>
            <origin xyz="0.0 -0.33631463164746167 -0.33631463164746167" rpy="0 0 0"/>
            <geometry>
                <box size="0.6726292632949233 0.6726292632949233 0.6726292632949233" />
            </geometry>
        </collision>
    </link>
    <joint name="limb0link1_limb0link2" type="revolute">
       <parent link="limb0link1"/>
       <child  link="limb0link2"/>
       <origin rpy="0 0 0" xyz="0.0 -0.33631463164746167 -0.6726292632949233" />
     <axis xyz="0 0 1"/>
       <limit effort="0.0" lower="-3.14159" upper="3.14159" velocity="0.0"/>
    </joint>
    <link name="limb0link2">
        <inertial>
            <origin xyz="0.0 0.0 -0.2604707686840443" rpy="0 0 0"/>
            <mass value="1" />
            <inertia ixx="100" ixy="0" ixz="0" iyy="100" iyz="0" izz="100" />
        </inertial>
        <visual>
            <origin xyz="0.0 0.0 -0.2604707686840443" rpy="0 0 0"/>
            <geometry>
                <box size="0.5209415373680886 0.5209415373680886 0.5209415373680886" />
            </geometry>
            <material name="Green">
                <color rgba="0 1 0 1"/>
            </material>
        </visual>
        <collision>
            <origin xyz="0.0 0.0 -0.2604707686840443" rpy="0 0 0"/>
            <geometry>
                <box size="0.5209415373680886 0.5209415373680886 0.5209415373680886" />
            </geometry>
        </collision>
    </link>
    <joint name="Torso_limb1link0" type="revolute">
       <parent link="Torso"/>
       <child  link="limb1link0"/>
       <origin rpy="0 0 0" xyz="1 -1 3.0" />
     <axis xyz="1 1 0"/>
       <limit effort="0.0" lower="-3.14159" upper="3.14159" velocity="0.0"/>
    </joint>
    <link name="limb1link0">
        <inertial>
            <origin xyz="0.17854771668086333 -0.43921251150199014 0.0" rpy="0 0 0"/>
            <mass value="1" />
            <inertia ixx="100" ixy="0" ixz="0" iyy="100" iyz="0" izz="100" />
        </inertial>
        <visual>
            <origin xyz="0.17854771668086333 -0.43921251150199014 0.0" rpy="0 0 0"/>
            <geometry>
                <box size="0.35709543336172667 0.8784250230039803 0.3354011617061494" />
            </geometry>
            <material name="Cyan">
                <color rgba="0 1 1 1"/>
            </material>
        </visual>
        <collision>
            <origin xyz="0.17854771668086333 -0.43921251150199014 0.0" rpy="0 0 0"/>
            <geometry>
                <box size="0.35709543336172667 0.8784250230039803 0.3354011617061494" />
            </geometry>
        </collision>
    </link>
    <joint name="limb1link0_limb1link1" type="revolute">
       <parent link="limb1link0"/>
       <child  link="limb1link1"/>
       <origin rpy="0 0 0" xyz="0.17854771668086333 -0.43921251150199014 -0.1677005808530747" />
     <axis xyz="0 0 1"/>
       <limit effort="0.0" lower="-3.14159" upper="3.14159" velocity="0.0"/>
    </joint>
    <link name="limb1link1">
        <inertial>
            <origin xyz="0.0 0.0 -0.23832499177729982" rpy="0 0 0"/>
            <mass value="1" />
            <inertia ixx="100" ixy="0" ixz="0" iyy="100" iyz="0" izz="100" />
        </inertial>
        <visual>
            <origin xyz="0.0 0.0 -0.23832499177729982" rpy="0 0 0"/>
            <geometry>
                <box size="0.47664998355459964 0.47664998355459964 0.47664998355459964" />
            </geometry>
            <material name="Green">
                <color rgba="0 1 0 1"/>
            </material>
        </visual>
        <collision>
            <origin xyz="0.0 0.0 -0.23832499177729982" rpy="0 0 0"/>
            <geometry>
                <box size="0.47664998355459964 0.47664998355459964 0.47664998355459964" />
            </geometry>
        </collision>
    </link>
    <joint name="limb1link1_limb1link2" type="revolute">
       <parent link="limb1link1"/>
       <child  link="limb1link2"/>
       <origin rpy="0 0 0" xyz="-0.23832499177729982 0.0 -0.23832499177729982" />
     <axis xyz="1 0 0"/>
       <limit effort="0.0" lower="-3.14159" upper="3.14159" velocity="0.0"/>
    </joint>
    <link name="limb1link2">
        <inertial>
            <origin xyz="-0.11657084556315346 0.0 0.0" rpy="0 0 0"/>
            <mass value="1" />
            <inertia ixx="100" ixy="0" ixz="0" iyy="100" iyz="0" izz="100" />
        </inertial>
        <visual>
            <origin xyz="-0.11657084556315346 0.0 0.0" rpy="0 0 0"/>
            <geometry>
                <box size="0.23314169112630692 0.23314169112630692 0.23314169112630692" />
            </geometry>
            <material name="Green">
                <color rgba="0 1 0 1"/>
            </material>
        </visual>
        <collision>
            <origin xyz="-0.11657084556315346 0.0 0.0" rpy="0 0 0"/>
            <geometry>
                <box size="0.23314169112630692 0.23314169112630692 0.23314169112630692" />
            </geometry>
        </collision>
    </link>
    <joint name="Torso_limb2link0" type="revolute">
       <parent link="Torso"/>
       <child  link="limb2link0"/>
       <origin rpy="0 0 0" xyz="-1 1 3.0" />
     <axis xyz="1 1 0"/>
       <limit effort="0.0" lower="-3.14159" upper="3.14159" velocity="0.0"/>
    </joint>
    <link name="limb2link0">
        <inertial>
            <origin xyz="-0.15640129557128957 0.15640129557128957 0.0" rpy="0 0 0"/>
            <mass value="1" />
            <inertia ixx="100" ixy="0" ixz="0" iyy="100" iyz="0" izz="100" />
        </inertial>
        <visual>
            <origin xyz="-0.15640129557128957 0.15640129557128957 0.0" rpy="0 0 0"/>
            <geometry>
                <box size="0.31280259114257913 0.31280259114257913 0.31280259114257913" />
            </geometry>
            <material name="Cyan">
                <color rgba="0 1 1 1"/>
            </material>
        </visual>
        <collision>
            <origin xyz="-0.15640129557128957 0.15640129557128957 0.0" rpy="0 0 0"/>
            <geometry>
                <box size="0.31280259114257913 0.31280259114257913 0.31280259114257913" />
            </geometry>
        </collision>
    </link>
    <joint name="limb2link0_limb2link1" type="revolute">
       <parent link="limb2link0"/>
       <child  link="limb2link1"/>
       <origin rpy="0 0 0" xyz="-0.15640129557128957 0.0 -0.15640129557128957" />
     <axis xyz="0 1 1"/>
       <limit effort="0.0" lower="-3.14159" upper="3.14159" velocity="0.0"/>
    </joint>
    <link name="limb2link1">
        <inertial>
            <origin xyz="0.0 -0.33631463164746167 -0.33631463164746167" rpy="0 0 0"/>
            <mass value="1" />
            <inertia ixx="100" ixy="0" ixz="0" iyy="100" iyz="0" izz="100" />
        </inertial>
        <visual>
            <origin xyz="0.0 -0.33631463164746167 -0.33631463164746167" rpy="0 0 0"/>
            <geometry>
                <box size="0.6726292632949233 0.6726292632949233 0.6726292632949233" />
            </geometry>
            <material name="Green">
                <color rgba="0 1 0 1"/>
            </material>
        </visual>
        <collision>
            <origin xyz="0.0 -0.33631463164746167 -0.33631463164746167" rpy="0 0 0"/>
            <geometry>
                <box size="0.6726292632949233 0.6726292632949233 0.6726292632949233" />
            </geometry>
        </collision>
    </link>
    <joint name="limb2link1_limb2link2" type="revolute">
       <parent link="limb2link1"/>
       <child  link="limb2link2"/>
       <origin rpy="0 0 0" xyz="0.0 -0.33631463164746167 -0.6726292632949233" />
     <axis xyz="0 0 1"/>
       <limit effort="0.0" lower="-3.14159" upper="3.14159" velocity="0.0"/>
    </joint>
    <link name="limb2link2">
        <inertial>
            <origin xyz="0.0 0.0 -0.2604707686840443" rpy="0 0 0"/>
            <mass value="1" />
            <inertia ixx="100" ixy="0" ixz="0" iyy="100" iyz="0" izz="100" />
        </inertial>
        <visual>
            <origin xyz="0.0 0.0 -0.2604707686840443" rpy="0 0 0"/>
            <geometry>
                <box size="0.5209415373680886 0.5209415373680886 0.5209415373680886" />
            </geometry>
            <material name="Green">
                <color rgba="0 1 0 1"/>
            </material>
        </visual>
        <collision>
            <origin xyz="0.0 0.0 -0.2604707686840443" rpy="0 0 0"/>
            <geometry>
                <box size="0.5209415373680886 0.5209415373680886 0.5209415373680886" />
            </geometry>
        </collision>
    </link>
    <joint name="Torso_limb3link0" type="revolute">
       <parent link="Torso"/>
       <child  link="limb3link0"/>
       <origin rpy="0 0 0" xyz="-1 -1 3.0" />
     <axis xyz="1 1 0"/>
       <limit effort="0.0" lower="-3.14159" upper="3.14159" velocity="0.0"/>
    </joint>
    <link name="limb3link0">
        <inertial>
            <origin xyz="-0.17854771668086333 -0.43921251150199014 0.0" rpy="0 0 0"/>
            <mass value="1" />
            <inertia ixx="100" ixy="0" ixz="0" iyy="100" iyz="0" izz="100" />
        </inertial>
        <visual>
            <origin xyz="-0.17854771668086333 -0.43921251150199014 0.0" rpy="0 0 0"/>
            <geometry>
                <box size="0.35709543336172667 0.8784250230039803 0.3354011617061494" />
            </geometry>
            <material name="Cyan">
                <color rgba="0 1 1 1"/>
            </material>
        </visual>
        <collision>
            <origin xyz="-0.17854771668086333 -0.43921251150199014 0.0" rpy="0 0 0"/>
            <geometry>
                <box size="0.35709543336172667 0.8784250230039803 0.3354011617061494" />
            </geometry>
        </collision>
    </link>
    <joint name="limb3link0_limb3link1" type="revolute">
       <parent link="limb3link0"/>
       <child  link="limb3link1"/>
       <origin rpy="0 0 0" xyz="-0.17854771668086333 -0.43921251150199014 -0.1677005808530747" />
     <axis xyz="0 0 1"/>
       <limit effort="0.0" lower="-3.14159" upper="3.14159" velocity="0.0"/>
    </joint>
    <link name="limb3link1">
        <inertial>
            <origin xyz="0.0 0.0 -0.23832499177729982" rpy="0 0 0"/>
            <mass value="1" />
            <inertia ixx="100" ixy="0" ixz="0" iyy="100" iyz="0" izz="100" />
        </inertial>
        <visual>
            <origin xyz="0.0 0.0 -0.23832499177729982" rpy="0 0 0"/>
            <geometry>
                <box size="0.47664998355459964 0.47664998355459964 0.47664998355459964" />
            </geometry>
            <material name="Green">
                <color rgba="0 1 0 1"/>
            </material>
        </visual>
        <collision>
            <origin xyz="0.0 0.0 -0.23832499177729982" rpy="0 0 0"/>
            <geometry>
                <box size="0.47664998355459964 0.47664998355459964 0.47664998355459964" />
            </geometry>
        </collision>
    </link>
    <joint name="limb3link1_limb3link2" type="revolute">
       <parent link="limb3link1"/>
       <child  link="limb3link2"/>
       <origin rpy="0 0 0" xyz="0.23832499177729982 0.0 -0.23832499177729982" />
     <axis xyz="1 0 0"/>
       <limit effort="0.0" lower="-3.14159" upper="3.14159" velocity="0.0"/>
    </joint>
    <link name="limb3link2">
        <inertial>
            <origin xyz="0.11657084556315346 0.0 0.0" rpy="0 0 0"/>
            <mass value="1" />
            <inertia ixx="100" ixy="0" ixz="0" iyy="100" iyz="0" izz="100" />
        </inertial>
        <visual>
            <origin xyz="0.11657084556315346 0.0 0.0" rpy="0 0 0"/>
            <geometry>
                <box size="0.23314169112630692 0.23314169112630692 0.23314169112630692" />
            </geometry>
            <material name="Green">
                <color rgba="0 1 0 1"/>
            </material>
        </visual>
        <collision>
            <origin xyz="0.11657084556315346 0.0 0.0" rpy="0 0 0"/>
            <geometry>
                <box size="0.23314169112630692 0.23314169112630692 0.23314169112630692" />
            </geometry>
        </collision>
    </link>
</robot>